Workbook

Sheet Sheet1
A1: Name of Prodcust Group | B1: What section | C1: Which color they are | F1: House Hold and cleaning | J1: Toiletries and health | N1: Pets
A2: Washing machine | B2: HH LC | G2: 65 | H2: 34
A3: dishwasher | B3: HH LC | F3: Washing Machine | G3: WMP | H3: CO2 | J3: Toothpaste | K3: Price | L3: CO2 | N3: dog food | O3: Price | P3: CO2
A4: dish soap | B4: HH LC | F4: WM1 | G4: 6.56 | H4: 15 | J4: TP1 | K4: 4.5 | L4: 5 | N4: DF1 | O4: 20.1 | P4: 16
A5: washing fragrance pods | B5: HH LC | F5: WM2 | G5: 12 | H5: 10 | J5: TP2 | K5: 3.95 | L5: 9 | N5: DF2 | O5: 15 | P5: 18
A6: kitchen roll | B6: HH LC | F6: WM3 | G6: 11.8 | H6: 9 | J6: TP3 | K6: 0.95 | L6: 7 | N6: DF3 | O6: 14 | P6: 17
A7: toilet roll | B7: HH LC | F7: WM4 | G7: 12 | H7: 8 | J7: TP4 | K7: 6.5 | L7: 8 | N7: DF4 | O7: 19 | P7: 21
A8: bin bags | B8: HH LC | F8: WM5 | G8: 0 | H8: 0 | J8: TP5 | K8: 0 | L8: 0 | N8: DF5 | O8: =O32*O10/(O10-5) -> 0 | P8: =P32*P10/(P10-5) -> 0
A9: Toothpaste | B9: Toiletries and health | F9: WM6 | G9: 0 | H9: 0 | J9: TP6 | K9: 0 | L9: 0 | N9: DF6 | O9: =O33*O10/(O10-10) -> 0 | P9: =P33*P10/(P10-10) -> 0
A10: hand soap | B10: Toiletries and health | F10: scrambler | G10: 56 | H10: 43 | J10: TP7 | K10: 84 | L10: 76 | N10: DF7 | O10: 74 | P10: 56
A11: deoderant | B11: Toiletries and health | F11: Dishwasher | G11: Price | H11: CO2 | J11: hand soap | K11: Price | L11: CO2 | N11: cat food | O11: Price | P11: CO2
A12: shampoo | B12: Toiletries and health | F12: DW1 | G12: 2 | H12: 8 | J12: HS1 | K12: 2 | L12: 6 | N12: CF1 | O12: 3.9 | P12: 8
A13: body wash | B13: Toiletries and health | F13: DW2 | G13: 5 | H13: 6 | J13: HS2 | K13: 0.59 | L13: 5 | N13: CF2 | O13: 5 | P13: 6
A14: conditioner | B14: Toiletries and health | F14: DW3 | G14: 5.5 | H14: 5 | J14: HS3 | K14: 2.5 | L14: 3 | N14: CF3 | O14: 4.9 | P14: 9
A15: dog food | B15: Pets | F15: DW4 | G15: 7.5 | H15: 2 | J15: HS4 | K15: 3 | L15: 7 | N15: CF4 | O15: 6 | P15: 3
A16: cat food | B16: Pets | F16: DW5 | G16: 0 | H16: 0 | J16: HS5 | K16: 0 | L16: 0 | N16: CF5 | O16: =O40*O18/(O18-5) -> 0 | P16: =P40*P18/(P18-5) -> 0
F17: DW6 | G17: 0 | H17: 0 | J17: HS6 | K17: 0 | L17: 0 | N17: CF6 | O17: =O41*O18/(O18-10) -> 0 | P17: =P41*P18/(P18-10) -> 0
F18: DW7 | G18: 0 | H18: 0 | J18: HS7 | K18: 0 | L18: 0 | N18: CF7 | O18: 65 | P18: 74
F19: Dish soap | G19: Price | H19: CO2 | J19: deoderant | K19: Price | L19: CO2
F20: DS1 | G20: 0.7 | H20: 6 | J20: DE1 | K20: 2.8 | L20: 2
A21: Low | F21: DS2 | G21: 1.5 | H21: 5 | J21: DE2 | K21: 6.6 | L21: 3
A22: 3 | B22: 4.8 | F22: DS3 | G22: 2.5 | H22: 2 | J22: DE3 | K22: 2.75 | L22: 2
A23: 3.5 | B23: 4.6 | F23: DS4 | G23: 1.5 | H23: 3 | J23: DE4 | K23: 1.95 | L23: 4
A24: 3.5 | B24: 4.2 | F24: DS5 | G24: 0 | H24: 0 | J24: DE5 | K24: 0 | L24: 0
A25: 4 | B25: 6 | F25: DS6 | G25: 0 | H25: 0 | J25: DE6 | K25: 0 | L25: 0
A26: 4 | B26: 3.7 | F26: DS7 | G26: 0 | H26: 0 | J26: DE7 | K26: 0 | L26: 0
A27: 4.5 | B27: 3.2 | F27: washing Fragrance Pods | G27: Price | H27: CO2 | J27: shampoo | K27: Price | L27: CO2
A28: Medium | F28: WFPN1 | G28: delete | H28: =H84*H34/(H34-10) -> 0 | J28: SH1 | K28: 4.25 | L28: 8
A29: 5 | B29: 6.7 | F29: WFPN2 | G29: =G85*G34/(G34-15) -> 0 | H29: =H85*H34/(H34-8) -> 0 | J29: SH2 | K29: 11.7 | L29: 6
A30: 5.5 | B30: 6.5 | F30: WFPN3 | G30: =G86*G34/(G34-20) -> 0 | H30: =H86*H34/(H34-7) -> 0 | J30: SH3 | K30: 15 | L30: 7
A31: 5.5 | B31: 6.2 | F31: WFPN4 | G31: =G87*G34/(G34-10) -> 0 | H31: =H87*H34/(H34-10) -> 0 | J31: SH4 | K31: 13.6 | L31: 4
A32: 6 | B32: 5.8 | F32: WFPN5 | G32: 0 | H32: 0 | J32: SH5 | K32: 0 | L32: 0
A33: 6 | B33: 5.1 | F33: WFPN6 | G33: 0 | H33: 0 | J33: SH6 | K33: 0 | L33: 0
A34: 6.5 | B34: 4.8 | F34: WFPN7 | G34: 0 | H34: 0 | J34: SH7 | K34: 0 | L34: 0
A35: High | F35: kitchen roll | G35: Price | H35: CO2 | J35: body wash | K35: Price | L35: CO2
A36: 10 | B36: 13.9 | F36: KR1 | G36: 5 | H36: 5 | J36: BW1 | K36: 2.1 | L36: 8
A37: 12 | B37: 13.1 | F37: KR2 | G37: 4 | H37: 8 | J37: BW2 | K37: 1.9 | L37: 6
A38: 12 | B38: 12.9 | F38: KR3 | G38: 3.9 | H38: 6 | J38: BW3 | K38: 2.4 | L38: 4
A39: 12.5 | B39: 12.5 | F39: KR4 | G39: 2.5 | H39: 9 | J39: BW4 | K39: 2 | L39: 7
A40: 12.5 | B40: 12.1 | F40: KR5 | G40: 0 | H40: 0 | J40: BW5 | K40: 0 | L40: 0
...

Sheet Sheet2
A1: WMN | B1: WMP | C1: WMC | D1: DWN | E1: DWP | F1: DWC | G1: DSN | H1: DSP | I1: DSC | J1: WFPN | K1: WFPP | L1: WFPC | M1: KRN | N1: KRP | O1: KRC | P1: TRN | Q1: TRP | R1: TRC | S1: BBN | T1: BBP | U1: BBC | W1: TPN | X1: TPP | Y1: TPC | Z1: HSN | AA1: HSP | AB1: HSC | AC1: DEON | AD1: DEOP | AE1: DEOC | AF1: SHAN | AG1: SHAP | AH1: SHAC | AI1: BWN | AJ1: BWP | AK1: BWC | AL1: CONN | AM1: CONP | AN1: CONC | AP1: DFN | AQ1: DFP | AR1: DFC | AS1: CFN | AT1: CFP | AU1: CFC
A2: =Sheet1!F4 -> WM1 | B2: =Sheet1!G4 -> 6.56 | C2: =Sheet1!H4 -> 15 | D2: =Sheet1!F12 -> DW1 | E2: =Sheet1!G12 -> 2 | F2: =Sheet1!H12 -> 8 | G2: =Sheet1!F20 -> DS1 | H2: =Sheet1!G20 -> 0.7 | I2: =Sheet1!H20 -> 6 | J2: =Sheet1!F28 -> WFPN1 | K2: 0 | L2: =Sheet1!H28 -> 0 | M2: =Sheet1!F36 -> KR1 | N2: =Sheet1!G36 -> 5 | O2: =Sheet1!H36 -> 5 | P2: =Sheet1!F44 -> TR1 | Q2: =Sheet1!G44 -> 13.3 | R2: =Sheet1!H44 -> 7 | S2: =Sheet1!F52 -> BB1 | T2: =Sheet1!G52 -> 4.25 | U2: =Sheet1!H52 -> 9 | W2: =Sheet1!J4 -> TP1 | X2: =Sheet1!K4 -> 4.5 | Y2: =Sheet1!L4 -> 5 | Z2: =Sheet1!J12 -> HS1 | AA2: =Sheet1!K12 -> 2 | AB2: =Sheet1!L12 -> 6 | AC2: =Sheet1!J20 -> DE1 | AD2: =Sheet1!K20 -> 2.8 | AE2: =Sheet1!L20 -> 2 | AF2: =Sheet1!J28 -> SH1 | AG2: =Sheet1!K28 -> 4.25 | AH2: =Sheet1!L28 -> 8 | AI2: =Sheet1!J36 -> BW1 | AJ2: =Sheet1!K36 -> 2.1 | AK2: =Sheet1!L36 -> 8 | AL2: =Sheet1!J44 -> CO1 | AM2: =Sheet1!K44 -> 7.5 | AN2: =Sheet1!L44 -> 5 | AP2: =Sheet1!N4 -> DF1 | AQ2: =Sheet1!O4 -> 20.1 | AR2: =Sheet1!P4 -> 16 | AS2: =Sheet1!N12 -> CF1 | AT2: =Sheet1!O12 -> 3.9 | AU2: =Sheet1!P12 -> 8
A3: =Sheet1!F5 -> WM2 | B3: =Sheet1!G5 -> 12 | C3: =Sheet1!H5 -> 10 | D3: =Sheet1!F13 -> DW2 | E3: =Sheet1!G13 -> 5 | F3: =Sheet1!H13 -> 6 | G3: =Sheet1!F21 -> DS2 | H3: =Sheet1!G21 -> 1.5 | I3: =Sheet1!H21 -> 5 | J3: =Sheet1!F29 -> WFPN2 | K3: =Sheet1!G29 -> 0 | L3: =Sheet1!H29 -> 0 | M3: =Sheet1!F37 -> KR2 | N3: =Sheet1!G37 -> 4 | O3: =Sheet1!H37 -> 8 | P3: =Sheet1!F45 -> TR2 | Q3: =Sheet1!G45 -> 12 | R3: =Sheet1!H45 -> 11 | S3: =Sheet1!F53 -> BB2 | T3: =Sheet1!G53 -> 12.5 | U3: =Sheet1!H53 -> 6 | W3: =Sheet1!J5 -> TP2 | X3: =Sheet1!K5 -> 3.95 | Y3: =Sheet1!L5 -> 9 | Z3: =Sheet1!J13 -> HS2 | AA3: =Sheet1!K13 -> 0.59 | AB3: =Sheet1!L13 -> 5 | AC3: =Sheet1!J21 -> DE2 | AD3: =Sheet1!K21 -> 6.6 | AE3: =Sheet1!L21 -> 3 | AF3: =Sheet1!J29 -> SH2 | AG3: =Sheet1!K29 -> 11.7 | AH3: =Sheet1!L29 -> 6 | AI3: =Sheet1!J37 -> BW2 | AJ3: =Sheet1!K37 -> 1.9 | AK3: =Sheet1!L37 -> 6 | AL3: =Sheet1!J45 -> CO2 | AM3: =Sheet1!K45 -> 5.5 | AN3: =Sheet1!L45 -> 10 | AP3: =Sheet1!N5 -> DF2 | AQ3: =Sheet1!O5 -> 15 | AR3: =Sheet1!P5 -> 18 | AS3: =Sheet1!N13 -> CF2 | AT3: =Sheet1!O13 -> 5 | AU3: =Sheet1!P13 -> 6
A4: =Sheet1!F6 -> WM3 | B4: =Sheet1!G6 -> 11.8 | C4: =Sheet1!H6 -> 9 | D4: =Sheet1!F14 -> DW3 | E4: =Sheet1!G14 -> 5.5 | F4: =Sheet1!H14 -> 5 | G4: =Sheet1!F22 -> DS3 | H4: =Sheet1!G22 -> 2.5 | I4: =Sheet1!H22 -> 2 | J4: =Sheet1!F30 -> WFPN3 | K4: =Sheet1!G30 -> 0 | L4: =Sheet1!H30 -> 0 | M4: =Sheet1!F38 -> KR3 | N4: =Sheet1!G38 -> 3.9 | O4: =Sheet1!H38 -> 6 | P4: =Sheet1!F46 -> TR3 | Q4: =Sheet1!G46 -> 14 | R4: =Sheet1!H46 -> 9 | S4: =Sheet1!F54 -> BB3 | T4: =Sheet1!G54 -> 15 | U4: =Sheet1!H54 -> 5 | W4: =Sheet1!J6 -> TP3 | X4: =Sheet1!K6 -> 0.95 | Y4: =Sheet1!L6 -> 7 | Z4: =Sheet1!J14 -> HS3 | AA4: =Sheet1!K14 -> 2.5 | AB4: =Sheet1!L14 -> 3 | AC4: =Sheet1!J22 -> DE3 | AD4: =Sheet1!K22 -> 2.75 | AE4: =Sheet1!L22 -> 2 | AF4: =Sheet1!J30 -> SH3 | AG4: =Sheet1!K30 -> 15 | AH4: =Sheet1!L30 -> 7 | AI4: =Sheet1!J38 -> BW3 | AJ4: =Sheet1!K38 -> 2.4 | AK4: =Sheet1!L38 -> 4 | AL4: =Sheet1!J46 -> CO3 | AM4: =Sheet1!K46 -> 0.95 | AN4: =Sheet1!L46 -> 8 | AP4: =Sheet1!N6 -> DF3 | AQ4: =Sheet1!O6 -> 14 | AR4: =Sheet1!P6 -> 17 | AS4: =Sheet1!N14 -> CF3 | AT4: =Sheet1!O14 -> 4.9 | AU4: =Sheet1!P14 -> 9
A5: =Sheet1!F7 -> WM4 | B5: =Sheet1!G7 -> 12 | C5: =Sheet1!H7 -> 8 | D5: =Sheet1!F15 -> DW4 | E5: =Sheet1!G15 -> 7.5 | F5: =Sheet1!H15 -> 2 | G5: =Sheet1!F23 -> DS4 | H5: =Sheet1!G23 -> 1.5 | I5: =Sheet1!H23 -> 3 | J5: =Sheet1!F31 -> WFPN4 | K5: =Sheet1!G31 -> 0 | L5: =Sheet1!H31 -> 0 | M5: =Sheet1!F39 -> KR4 | N5: =Sheet1!G39 -> 2.5 | O5: =Sheet1!H39 -> 9 | P5: =Sheet1!F47 -> TR4 | Q5: =Sheet1!G47 -> 10.6 | R5: =Sheet1!H47 -> 10 | S5: =Sheet1!F55 -> BB4 | T5: =Sheet1!G55 -> 8 | U5: =Sheet1!H55 -> 8 | W5: =Sheet1!J7 -> TP4 | X5: =Sheet1!K7 -> 6.5 | Y5: =Sheet1!L7 -> 8 | Z5: =Sheet1!J15 -> HS4 | AA5: =Sheet1!K15 -> 3 | AB5: =Sheet1!L15 -> 7 | AC5: =Sheet1!J23 -> DE4 | AD5: =Sheet1!K23 -> 1.95 | AE5: =Sheet1!L23 -> 4 | AF5: =Sheet1!J31 -> SH4 | AG5: =Sheet1!K31 -> 13.6 | AH5: =Sheet1!L31 -> 4 | AI5: =Sheet1!J39 -> BW4 | AJ5: =Sheet1!K39 -> 2 | AK5: =Sheet1!L39 -> 7 | AL5: =Sheet1!J47 -> CO4 | AM5: =Sheet1!K47 -> 6.2 | AN5: =Sheet1!L47 -> 6 | AP5: =Sheet1!N7 -> DF4 | AQ5: =Sheet1!O7 -> 19 | AR5: =Sheet1!P7 -> 21 | AS5: =Sheet1!N15 -> CF4 | AT5: =Sheet1!O15 -> 6 | AU5: =Sheet1!P15 -> 3
